<robot
  name="Humanas">
  <link
    name="Chest`">
    <inertial>
      <origin
        xyz="0.03889 -0.011045 0.28695"
        rpy="0 0 0" />
      <mass
        value="0.55321" />
      <inertia
        ixx="0.00083654"
        ixy="-9.4496E-07"
        ixz="2.8804E-06"
        iyy="0.0008015"
        iyz="3.2896E-06"
        izz="0.001092" />
    </inertial>
    <visual>
      <origin
        xyz="0 0 0"
        rpy="0 0 0" />
      <geometry>
        <mesh
          filename="package://Humanas/meshes/Chest`.STL" />
      </geometry>
      <material
        name="">
        <color
          rgba="1 1 1 1" />
      </material>
    </visual>
    <collision>
      <origin
        xyz="0 0 0"
        rpy="0 0 0" />
      <geometry>
        <mesh
          filename="package://Humanas/meshes/Chest`.STL" />
      </geometry>
    </collision>
  </link>
  <link
    name="Right Hip Yaw">
    <inertial>
      <origin
        xyz="3.9107E-05 0.013044 -0.020682"
        rpy="0 0 0" />
      <mass
        value="0.014477" />
      <inertia
        ixx="1.1485E-05"
        ixy="-5.251E-08"
        ixz="-1.2035E-08"
        iyy="2.0242E-06"
        iyz="-2.0997E-08"
        izz="1.1214E-05" />
    </inertial>
    <visual>
      <origin
        xyz="0 0 0"
        rpy="0 0 0" />
      <geometry>
        <mesh
          filename="package://Humanas/meshes/Right Hip Yaw.STL" />
      </geometry>
      <material
        name="">
        <color
          rgba="1 1 1 1" />
      </material>
    </visual>
    <collision>
      <origin
        xyz="0 0 0"
        rpy="0 0 0" />
      <geometry>
        <mesh
          filename="package://Humanas/meshes/Right Hip Yaw.STL" />
      </geometry>
    </collision>
  </link>
  <joint
    name="Right Hip Yaw"
    type="revolute">
    <origin
      xyz="0.0525081749734009 -0.0494090455531854 0.209500255956078"
      rpy="3.1414865080468 -1.99840144432528E-15 -1.57079632679489" />
    <parent
      link="Chest`" />
    <child
      link="Right Hip Yaw" />
    <axis
      xyz="0 0 1" />
  </joint>
  <link
    name="Right_Hip_Roll">
    <inertial>
      <origin
        xyz="0.0036626 0.0016981 -0.010906"
        rpy="0 0 0" />
      <mass
        value="0.0041374" />
      <inertia
        ixx="8.4418E-07"
        ixy="-4.0716E-08"
        ixz="2.214E-07"
        iyy="9.26E-07"
        iyz="9.736E-08"
        izz="8.9678E-07" />
    </inertial>
    <visual>
      <origin
        xyz="0 0 0"
        rpy="0 0 0" />
      <geometry>
        <mesh
          filename="package://Humanas/meshes/Right_Hip_Roll.STL" />
      </geometry>
      <material
        name="">
        <color
          rgba="1 1 1 1" />
      </material>
    </visual>
    <collision>
      <origin
        xyz="0 0 0"
        rpy="0 0 0" />
      <geometry>
        <mesh
          filename="package://Humanas/meshes/Right_Hip_Roll.STL" />
      </geometry>
    </collision>
  </link>
  <joint
    name="Right_hip_roll"
    type="revolute">
    <origin
      xyz="0 0 0"
      rpy="1.5708 -1.5708 0" />
    <parent
      link="Right Hip Yaw" />
    <child
      link="Right_Hip_Roll" />
    <axis
      xyz="0 0 1" />
    <limit
      effort="0"
      velocity="0" />
  </joint>
  <link
    name="Right Hip Pitch">
    <inertial>
      <origin
        xyz="0.0346907629410989 0.000450008480619157 0.00113131138938455"
        rpy="0 0 0" />
      <mass
        value="0.0111620558640124" />
      <inertia
        ixx="3.60770980269073E-06"
        ixy="5.35578878730595E-08"
        ixz="-2.58388515292259E-07"
        iyy="7.73574611316047E-06"
        iyz="-3.3518151021984E-09"
        izz="5.24114704838464E-06" />
    </inertial>
    <visual>
      <origin
        xyz="0 0 0"
        rpy="0 0 0" />
      <geometry>
        <mesh
          filename="package://Humanas/meshes/Right Hip Pitch.STL" />
      </geometry>
      <material
        name="">
        <color
          rgba="1 1 1 1" />
      </material>
    </visual>
    <collision>
      <origin
        xyz="0 0 0"
        rpy="0 0 0" />
      <geometry>
        <mesh
          filename="package://Humanas/meshes/Right Hip Pitch.STL" />
      </geometry>
    </collision>
  </link>
  <joint
    name="right_hip_pitch"
    type="revolute">
    <origin
      xyz="0 0 0"
      rpy="1.5708 0 -5.5511E-17" />
    <parent
      link="Right_Hip_Roll" />
    <child
      link="Right Hip Pitch" />
    <axis
      xyz="0 0 1" />
    <limit
      effort="0"
      velocity="0" />
  </joint>
  <link
    name="Right Knee Pitch">
    <inertial>
      <origin
        xyz="0.077708 -0.0062948 0.0027729"
        rpy="0 0 0" />
      <mass
        value="0.024625" />
      <inertia
        ixx="1.0805E-05"
        ixy="3.5639E-06"
        ixz="-1.5493E-09"
        iyy="3.0427E-05"
        iyz="2.6511E-10"
        izz="2.6098E-05" />
    </inertial>
    <visual>
      <origin
        xyz="0 0 0"
        rpy="0 0 0" />
      <geometry>
        <mesh
          filename="package://Humanas/meshes/Right Knee Pitch.STL" />
      </geometry>
      <material
        name="">
        <color
          rgba="1 1 1 1" />
      </material>
    </visual>
    <collision>
      <origin
        xyz="0 0 0"
        rpy="0 0 0" />
      <geometry>
        <mesh
          filename="package://Humanas/meshes/Right Knee Pitch.STL" />
      </geometry>
    </collision>
  </link>
  <joint
    name="right_knee_pitch"
    type="revolute">
    <origin
      xyz="0.047318 0.00082452 0.00023281"
      rpy="1.1657E-15 -2.6645E-15 0.012971" />
    <parent
      link="Right Hip Pitch" />
    <child
      link="Right Knee Pitch" />
    <axis
      xyz="0 0 1" />
    <limit
      effort="0"
      velocity="0" />
  </joint>
  <link
    name="Right Ankle Pitch">
    <inertial>
      <origin
        xyz="-0.0032513 -0.0099245 -0.00051655"
        rpy="0 0 0" />
      <mass
        value="0.0043256" />
      <inertia
        ixx="9.8157E-07"
        ixy="-1.8027E-07"
        ixz="-1.1889E-08"
        iyy="9.5387E-07"
        iyz="-5.085E-08"
        izz="1.0452E-06" />
    </inertial>
    <visual>
      <origin
        xyz="0 0 0"
        rpy="0 0 0" />
      <geometry>
        <mesh
          filename="package://Humanas/meshes/Right Ankle Pitch.STL" />
      </geometry>
      <material
        name="">
        <color
          rgba="1 1 1 1" />
      </material>
    </visual>
    <collision>
      <origin
        xyz="0 0 0"
        rpy="0 0 0" />
      <geometry>
        <mesh
          filename="package://Humanas/meshes/Right Ankle Pitch.STL" />
      </geometry>
    </collision>
  </link>
  <joint
    name="right_ankle_pitch"
    type="revolute">
    <origin
      xyz="0.134152567134725 -0.000210688409827076 0.000795604196405918"
      rpy="-5.55111512312578E-17 4.16333634234434E-16 -0.0130774152250385" />
    <parent
      link="Right Knee Pitch" />
    <child
      link="Right Ankle Pitch" />
    <axis
      xyz="0 0 1" />
  </joint>
  <link
    name="Right Ankle Roll">
    <inertial>
      <origin
        xyz="0.023558 0.0050845 0.013036"
        rpy="0 0 0" />
      <mass
        value="0.028663" />
      <inertia
        ixx="3.2532E-05"
        ixy="4.2557E-07"
        ixz="1.2343E-08"
        iyy="2.6101E-05"
        iyz="2.5007E-09"
        izz="9.2319E-06" />
    </inertial>
    <visual>
      <origin
        xyz="0 0 0"
        rpy="0 0 0" />
      <geometry>
        <mesh
          filename="package://Humanas/meshes/Right Ankle Roll.STL" />
      </geometry>
      <material
        name="">
        <color
          rgba="1 1 1 1" />
      </material>
    </visual>
    <collision>
      <origin
        xyz="0 0 0"
        rpy="0 0 0" />
      <geometry>
        <mesh
          filename="package://Humanas/meshes/Right Ankle Roll.STL" />
      </geometry>
    </collision>
  </link>
  <joint
    name="right_ankle_roll"
    type="revolute">
    <origin
      xyz="0 0 0"
      rpy="-1.5707963267949 -5.55111512312578E-17 0" />
    <parent
      link="Right Ankle Pitch" />
    <child
      link="Right Ankle Roll" />
    <axis
      xyz="0 0 0.999999999961933" />
  </joint>
  <link
    name="Left Hip Yaw">
    <inertial>
      <origin
        xyz="0.00040394 0.013044 -0.020682"
        rpy="0 0 0" />
      <mass
        value="0.014477" />
      <inertia
        ixx="1.1485E-05"
        ixy="1.8119E-08"
        ixz="-3.1075E-10"
        iyy="2.0233E-06"
        iyz="-2.0997E-08"
        izz="1.1213E-05" />
    </inertial>
    <visual>
      <origin
        xyz="0 0 0"
        rpy="0 0 0" />
      <geometry>
        <mesh
          filename="package://Humanas/meshes/Left Hip Yaw.STL" />
      </geometry>
      <material
        name="">
        <color
          rgba="1 1 1 1" />
      </material>
    </visual>
    <collision>
      <origin
        xyz="0 0 0"
        rpy="0 0 0" />
      <geometry>
        <mesh
          filename="package://Humanas/meshes/Left Hip Yaw.STL" />
      </geometry>
    </collision>
  </link>
  <joint
    name="Left Hip Yaw"
    type="revolute">
    <origin
      xyz="0.052508 0.027595 0.2095"
      rpy="3.1415 4.4964E-15 -1.5708" />
    <parent
      link="Chest`" />
    <child
      link="Left Hip Yaw" />
    <axis
      xyz="0 0 1" />
    <limit
      effort="0"
      velocity="0" />
  </joint>
  <link
    name="Left Hip Roll">
    <inertial>
      <origin
        xyz="0.0032131 -0.00080896 -0.0099113"
        rpy="0 0 0" />
      <mass
        value="0.0043256" />
      <inertia
        ixx="9.8068E-07"
        ixy="1.6661E-08"
        ixz="1.7886E-07"
        iyy="1.0408E-06"
        iyz="-4.5835E-08"
        izz="9.5785E-07" />
    </inertial>
    <visual>
      <origin
        xyz="0 0 0"
        rpy="0 0 0" />
      <geometry>
        <mesh
          filename="package://Humanas/meshes/Left Hip Roll.STL" />
      </geometry>
      <material
        name="">
        <color
          rgba="0.75294 0.75294 0.75294 1" />
      </material>
    </visual>
    <collision>
      <origin
        xyz="0 0 0"
        rpy="0 0 0" />
      <geometry>
        <mesh
          filename="package://Humanas/meshes/Left Hip Roll.STL" />
      </geometry>
    </collision>
  </link>
  <joint
    name="Left Hip Roll"
    type="revolute">
    <origin
      xyz="0 0 0"
      rpy="-1.86929525838108 -1.57079630572147 0" />
    <parent
      link="Left Hip Yaw" />
    <child
      link="Left Hip Roll" />
    <axis
      xyz="0 0 1" />
  </joint>
  <link
    name="Left Hip Pitch">
    <inertial>
      <origin
        xyz="0.034694 1.6058E-10 0.0011274"
        rpy="0 0 0" />
      <mass
        value="0.011162" />
      <inertia
        ixx="3.607E-06"
        ixy="1.9136E-14"
        ixz="-2.5841E-07"
        iyy="7.7364E-06"
        iyz="-1.1975E-15"
        izz="5.2411E-06" />
    </inertial>
    <visual>
      <origin
        xyz="0 0 0"
        rpy="0 0 0" />
      <geometry>
        <mesh
          filename="package://Humanas/meshes/Left Hip Pitch.STL" />
      </geometry>
      <material
        name="">
        <color
          rgba="1 1 1 1" />
      </material>
    </visual>
    <collision>
      <origin
        xyz="0 0 0"
        rpy="0 0 0" />
      <geometry>
        <mesh
          filename="package://Humanas/meshes/Left Hip Pitch.STL" />
      </geometry>
    </collision>
  </link>
  <joint
    name="Left Hip {itch"
    type="revolute">
    <origin
      xyz="0 0 0"
      rpy="-1.5707963267949 0 -2.77555756156289E-17" />
    <parent
      link="Left Hip Roll" />
    <child
      link="Left Hip Pitch" />
    <axis
      xyz="0 0 -1" />
  </joint>
  <link
    name="Left Knee Pitch">
    <inertial>
      <origin
        xyz="0.035556 0.0060842 0.0018882"
        rpy="0 0 0" />
      <mass
        value="0.024625" />
      <inertia
        ixx="1.0805E-05"
        ixy="-3.5639E-06"
        ixz="1.5493E-09"
        iyy="3.0427E-05"
        iyz="2.6511E-10"
        izz="2.6098E-05" />
    </inertial>
    <visual>
      <origin
        xyz="0 0 0"
        rpy="0 0 0" />
      <geometry>
        <mesh
          filename="package://Humanas/meshes/Left Knee Pitch.STL" />
      </geometry>
      <material
        name="">
        <color
          rgba="1 1 1 1" />
      </material>
    </visual>
    <collision>
      <origin
        xyz="0 0 0"
        rpy="0 0 0" />
      <geometry>
        <mesh
          filename="package://Humanas/meshes/Left Knee Pitch.STL" />
      </geometry>
    </collision>
  </link>
  <joint
    name="Left Knee Pitch"
    type="revolute">
    <origin
      xyz="0.089478 0 0.00111"
      rpy="-1.3933E-14 -4.6074E-15 0.0005039" />
    <parent
      link="Left Hip Pitch" />
    <child
      link="Left Knee Pitch" />
    <axis
      xyz="0 0 -1" />
    <limit
      effort="0"
      velocity="0" />
  </joint>
  <link
    name="Left Ankle Pitch">
    <inertial>
      <origin
        xyz="-0.0031966 0.0099113 -0.0011061"
        rpy="0 0 0" />
      <mass
        value="0.0043256" />
      <inertia
        ixx="9.7541E-07"
        ixy="1.7936E-07"
        ixz="-1.9038E-08"
        iyy="9.5274E-07"
        iyz="4.0257E-08"
        izz="1.041E-06" />
    </inertial>
    <visual>
      <origin
        xyz="0 0 0"
        rpy="0 0 0" />
      <geometry>
        <mesh
          filename="package://Humanas/meshes/Left Ankle Pitch.STL" />
      </geometry>
      <material
        name="">
        <color
          rgba="1 1 1 1" />
      </material>
    </visual>
    <collision>
      <origin
        xyz="0 0 0"
        rpy="0 0 0" />
      <geometry>
        <mesh
          filename="package://Humanas/meshes/Left Ankle Pitch.STL" />
      </geometry>
    </collision>
  </link>
  <joint
    name="Left Ankle Pitch"
    type="revolute">
    <origin
      xyz="0.0919999999999788 0 0.000352375812201378"
      rpy="2.1094237467878E-15 2.58126853225349E-15 -0.000503903428732216" />
    <parent
      link="Left Knee Pitch" />
    <child
      link="Left Ankle Pitch" />
    <axis
      xyz="0 0 -1" />
  </joint>
  <link
    name="Left Ankle Roll">
    <inertial>
      <origin
        xyz="0.023584 -0.0038509 0.010339"
        rpy="0 0 0" />
      <mass
        value="0.028663" />
      <inertia
        ixx="3.2422E-05"
        ixy="-3.3235E-07"
        ixz="-2.11E-07"
        iyy="2.6102E-05"
        iyz="1.6906E-07"
        izz="9.1249E-06" />
    </inertial>
    <visual>
      <origin
        xyz="0 0 0"
        rpy="0 0 0" />
      <geometry>
        <mesh
          filename="package://Humanas/meshes/Left Ankle Roll.STL" />
      </geometry>
      <material
        name="">
        <color
          rgba="1 1 1 1" />
      </material>
    </visual>
    <collision>
      <origin
        xyz="0 0 0"
        rpy="0 0 0" />
      <geometry>
        <mesh
          filename="package://Humanas/meshes/Left Ankle Roll.STL" />
      </geometry>
    </collision>
  </link>
  <joint
    name="Left Ankle Roll"
    type="revolute">
    <origin
      xyz="0 0 0"
      rpy="1.5707963267949 -8.32667268468867E-17 0" />
    <parent
      link="Left Ankle Pitch" />
    <child
      link="Left Ankle Roll" />
    <axis
      xyz="0 0 1" />
  </joint>
  <link
    name="Neck_Yaw">
    <inertial>
      <origin
        xyz="-1.75E-13 -7.6255E-12 0.0073613"
        rpy="0 0 0" />
      <mass
        value="0.0064977" />
      <inertia
        ixx="2.3735E-06"
        ixy="3.9996E-20"
        ixz="7.4115E-22"
        iyy="9.2167E-07"
        iyz="-6.5952E-18"
        izz="1.9849E-06" />
    </inertial>
    <visual>
      <origin
        xyz="0 0 0"
        rpy="0 0 0" />
      <geometry>
        <mesh
          filename="package://Humanas/meshes/Neck_Yaw.STL" />
      </geometry>
      <material
        name="">
        <color
          rgba="0.79216 0.81961 0.93333 1" />
      </material>
    </visual>
    <collision>
      <origin
        xyz="0 0 0"
        rpy="0 0 0" />
      <geometry>
        <mesh
          filename="package://Humanas/meshes/Neck_Yaw.STL" />
      </geometry>
    </collision>
  </link>
  <joint
    name="neck_yaw"
    type="revolute">
    <origin
      xyz="0.052888 -0.011205 0.37154"
      rpy="-4.1633E-16 0.00010615 8.3267E-16" />
    <parent
      link="Chest`" />
    <child
      link="Neck_Yaw" />
    <axis
      xyz="0 0 1" />
    <limit
      effort="0"
      velocity="0" />
  </joint>
  <link
    name="Head">
    <inertial>
      <origin
        xyz="6.9211E-13 1.7819E-13 -0.017876"
        rpy="0 0 0" />
      <mass
        value="0.00028715" />
      <inertia
        ixx="2.3043E-09"
        ixy="-9.6367E-23"
        ixz="-5.2861E-21"
        iyy="2.3043E-09"
        iyz="1.8663E-23"
        izz="3.1463E-09" />
    </inertial>
    <visual>
      <origin
        xyz="0 0 0"
        rpy="0 0 0" />
      <geometry>
        <mesh
          filename="package://Humanas/meshes/Head.STL" />
      </geometry>
      <material
        name="">
        <color
          rgba="0.75294 0.75294 0.75294 1" />
      </material>
    </visual>
    <collision>
      <origin
        xyz="0 0 0"
        rpy="0 0 0" />
      <geometry>
        <mesh
          filename="package://Humanas/meshes/Head.STL" />
      </geometry>
    </collision>
  </link>
  <joint
    name="head"
    type="revolute">
    <origin
      xyz="0 0 0.021"
      rpy="-0.37299 1.5708 1.2083" />
    <parent
      link="Neck_Yaw" />
    <child
      link="Head" />
    <axis
      xyz="0 0 1" />
    <limit
      effort="0"
      velocity="0" />
  </joint>
  <link
    name="Right_shoulder_pitch">
    <inertial>
      <origin
        xyz="0.003396 -0.00014174 0.011274"
        rpy="0 0 0" />
      <mass
        value="0.0075889" />
      <inertia
        ixx="3.0239E-06"
        ixy="-3.4542E-09"
        ixz="4.4636E-07"
        iyy="1.5524E-06"
        iyz="-7.9526E-09"
        izz="2.7529E-06" />
    </inertial>
    <visual>
      <origin
        xyz="0 0 0"
        rpy="0 0 0" />
      <geometry>
        <mesh
          filename="package://Humanas/meshes/Right_shoulder_pitch.STL" />
      </geometry>
      <material
        name="">
        <color
          rgba="0.79216 0.81961 0.93333 1" />
      </material>
    </visual>
    <collision>
      <origin
        xyz="0 0 0"
        rpy="0 0 0" />
      <geometry>
        <mesh
          filename="package://Humanas/meshes/Right_shoulder_pitch.STL" />
      </geometry>
    </collision>
  </link>
  <joint
    name="right_shoulder_pitch"
    type="revolute">
    <origin
      xyz="0.052662 -0.075992 0.34946"
      rpy="-1.5708 1.5707 3.1416" />
    <parent
      link="Chest`" />
    <child
      link="Right_shoulder_pitch" />
    <axis
      xyz="0 0 1" />
    <limit
      effort="0"
      velocity="0" />
  </joint>
  <link
    name="Right shoulder roll">
    <inertial>
      <origin
        xyz="0.039576 0.0011829 -0.001057"
        rpy="0 0 0" />
      <mass
        value="0.0038192" />
      <inertia
        ixx="6.9289E-07"
        ixy="1.827E-07"
        ixz="1.8296E-07"
        iyy="1.3051E-06"
        iyz="5.7953E-09"
        izz="1.2655E-06" />
    </inertial>
    <visual>
      <origin
        xyz="0 0 0"
        rpy="0 0 0" />
      <geometry>
        <mesh
          filename="package://Humanas/meshes/Right shoulder roll.STL" />
      </geometry>
      <material
        name="">
        <color
          rgba="0.75294 0.75294 0.75294 1" />
      </material>
    </visual>
    <collision>
      <origin
        xyz="0 0 0"
        rpy="0 0 0" />
      <geometry>
        <mesh
          filename="package://Humanas/meshes/Right shoulder roll.STL" />
      </geometry>
    </collision>
  </link>
  <joint
    name="right_shoulder_roll"
    type="revolute">
    <origin
      xyz="0.0149367315161067 -0.00179939209685259 0.0262626305729386"
      rpy="-1.57079632679493 8.72357741599217E-14 -0.00101844888208074" />
    <parent
      link="Right_shoulder_pitch" />
    <child
      link="Right shoulder roll" />
    <axis
      xyz="-0.00101844870600964 0 0.999999481380982" />
  </joint>
  <link
    name="Right Gripper">
    <inertial>
      <origin
        xyz="0.053103 7.8246E-05 0.0049652"
        rpy="0 0 0" />
      <mass
        value="0.034872" />
      <inertia
        ixx="6.9128E-06"
        ixy="2.9112E-08"
        ixz="1.741E-07"
        iyy="3.7986E-05"
        iyz="6.2476E-09"
        izz="3.9657E-05" />
    </inertial>
    <visual>
      <origin
        xyz="0 0 0"
        rpy="0 0 0" />
      <geometry>
        <mesh
          filename="package://Humanas/meshes/Right Gripper.STL" />
      </geometry>
      <material
        name="">
        <color
          rgba="0.79216 0.81961 0.93333 1" />
      </material>
    </visual>
    <collision>
      <origin
        xyz="0 0 0"
        rpy="0 0 0" />
      <geometry>
        <mesh
          filename="package://Humanas/meshes/Right Gripper.STL" />
      </geometry>
    </collision>
  </link>
  <joint
    name="right_gripper"
    type="revolute">
    <origin
      xyz="0.0791367595660936 0 0"
      rpy="1.57079632679505 -5.55111512312578E-17 0" />
    <parent
      link="Right shoulder roll" />
    <child
      link="Right Gripper" />
    <axis
      xyz="0 0 1" />
  </joint>
  <link
    name="Left shoulder Pitch">
    <inertial>
      <origin
        xyz="0.03889 -0.011045 0.28695"
        rpy="0 0 0" />
      <mass
        value="0.55321" />
      <inertia
        ixx="0.00083654"
        ixy="-9.4496E-07"
        ixz="2.8804E-06"
        iyy="0.0008015"
        iyz="3.2896E-06"
        izz="0.001092" />
    </inertial>
    <visual>
      <origin
        xyz="0 0 0"
        rpy="0 0 0" />
      <geometry>
        <mesh
          filename="package://Humanas/meshes/Left shoulder Pitch.STL" />
      </geometry>
      <material
        name="">
        <color
          rgba="1 1 1 1" />
      </material>
    </visual>
    <collision>
      <origin
        xyz="0 0 0"
        rpy="0 0 0" />
      <geometry>
        <mesh
          filename="package://Humanas/meshes/Left shoulder Pitch.STL" />
      </geometry>
    </collision>
  </link>
  <joint
    name="left_shoulder_pitch"
    type="revolute">
    <origin
      xyz="0.0525317436560445 0.0553948487444451 0.350540254248906"
      rpy="1.57079632680326 1.57069018124965 -3.14159265358116" />
    <parent
      link="Chest`" />
    <child
      link="Left shoulder Pitch" />
    <axis
      xyz="0 0 1" />
  </joint>
  <link
    name="Left shoulder Roll">
    <inertial>
      <origin
        xyz="0.039561 -0.0012125 -0.0014829"
        rpy="0 0 0" />
      <mass
        value="0.0038192" />
      <inertia
        ixx="6.9409E-07"
        ixy="-1.8335E-07"
        ixz="1.905E-07"
        iyy="1.306E-06"
        iyz="-5.5256E-09"
        izz="1.2665E-06" />
    </inertial>
    <visual>
      <origin
        xyz="0 0 0"
        rpy="0 0 0" />
      <geometry>
        <mesh
          filename="package://Humanas/meshes/Left shoulder Roll.STL" />
      </geometry>
      <material
        name="">
        <color
          rgba="0.75294 0.75294 0.75294 1" />
      </material>
    </visual>
    <collision>
      <origin
        xyz="0 0 0"
        rpy="0 0 0" />
      <geometry>
        <mesh
          filename="package://Humanas/meshes/Left shoulder Roll.STL" />
      </geometry>
    </collision>
  </link>
  <joint
    name="left_shoulder_roll"
    type="revolute">
    <origin
      xyz="0.0159999999999996 0.00114999999999846 0.0244494897427823"
      rpy="1.57079632679487 -3.80806497446429E-14 2.10387263166467E-14" />
    <parent
      link="Left shoulder Pitch" />
    <child
      link="Left shoulder Roll" />
    <axis
      xyz="0 0 1" />
  </joint>
  <link
    name="Left Gripper">
    <inertial>
      <origin
        xyz="0.052877 0.0012541 0.0049953"
        rpy="0 0 0" />
      <mass
        value="0.035051" />
      <inertia
        ixx="6.9541E-06"
        ixy="7.2748E-07"
        ixz="1.169E-07"
        iyy="3.8311E-05"
        iyz="8.7662E-09"
        izz="3.9986E-05" />
    </inertial>
    <visual>
      <origin
        xyz="0 0 0"
        rpy="0 0 0" />
      <geometry>
        <mesh
          filename="package://Humanas/meshes/Left Gripper.STL" />
      </geometry>
      <material
        name="">
        <color
          rgba="0.79216 0.81961 0.93333 1" />
      </material>
    </visual>
    <collision>
      <origin
        xyz="0 0 0"
        rpy="0 0 0" />
      <geometry>
        <mesh
          filename="package://Humanas/meshes/Left Gripper.STL" />
      </geometry>
    </collision>
  </link>
  <joint
    name="left_gripper"
    type="revolute">
    <origin
      xyz="0.0791563548332389 0 0"
      rpy="-1.57079632679495 0 2.77555756156289E-17" />
    <parent
      link="Left shoulder Roll" />
    <child
      link="Left Gripper" />
    <axis
      xyz="0 0 1" />
  </joint>
</robot>